Workbook

Sheet How to use
A1: SMP 26ACS01 — Refractometer data collection
A3: Fill only the YELLOW cells. Everything blue-grey is a formula — do not type over it.
A5: WHAT TO RECORD PER TRIAL
A6: The firmware prints one line per measurement over the serial link at 9600 baud:
A7: steps=… angle=… incident=… case=… dark=… bright=… n=…
A8: Copy 'angle', 'incident', 'case' and 'n' into the sheet. Five trials per liquid.
A9: Empty, rinse and refill the cell between trials — otherwise you measure the same drop five times
A10: and the standard error will be far smaller than the true repeatability.
A12: Also copy the 'profile:' line for at least one trial per liquid. That array is Figure 4.
A14: SHEETS
A15: T1 raw readings 5 trials × 5 liquids. Computes mean, SD, standard error and % deviation.
A16: T1 summary Table 1 exactly as it appears in the paper — copy this across.
... A24: Quote it to one significant figure and round the mean to match. Do not write 62.4531 ± 0.0087.

Sheet T1 raw readings
A1: Table 1 — raw readings, five trials per liquid
A2: Yellow = type the value the firmware printed. Blue-grey = computed.
A4: Liquid / trial | B4: Stage angle φ /° | C4: Incident α /° | D4: Case (1 or 2) | E4: n reported by device | F4: θc computed /° | G4: n check (1.50 sin θc)
A5: Deionised water
A6: trial 1 | F6: =IF(C6="","",IF(D6=1,45-DEGREES(ASIN(SIN(RADIANS(C6))/Conditions!$B$10)),45+DEGREES(ASIN(SIN(RADIANS(C6))/Conditions!$B$10)))) | G6: =IF(F6="","",Conditions!$B$10*SIN(RADIANS(F6)))
A7: trial 2 | F7: =IF(C7="","",IF(D7=1,45-DEGREES(ASIN(SIN(RADIANS(C7))/Conditions!$B$10)),45+DEGREES(ASIN(SIN(RADIANS(C7))/Conditions!$B$10)))) | G7: =IF(F7="","",Conditions!$B$10*SIN(RADIANS(F7)))
A8: trial 3 | F8: =IF(C8="","",IF(D8=1,45-DEGREES(ASIN(SIN(RADIANS(C8))/Conditions!$B$10)),45+DEGREES(ASIN(SIN(RADIANS(C8))/Conditions!$B$10)))) | G8: =IF(F8="","",Conditions!$B$10*SIN(RADIANS(F8)))
A9: trial 4 | F9: =IF(C9="","",IF(D9=1,45-DEGREES(ASIN(SIN(RADIANS(C9))/Conditions!$B$10)),45+DEGREES(ASIN(SIN(RADIANS(C9))/Conditions!$B$10)))) | G9: =IF(F9="","",Conditions!$B$10*SIN(RADIANS(F9)))
A10: trial 5 | F10: =IF(C10="","",IF(D10=1,45-DEGREES(ASIN(SIN(RADIANS(C10))/Conditions!$B$10)),45+DEGREES(ASIN(SIN(RADIANS(C10))/Conditions!$B$10)))) | G10: =IF(F10="","",Conditions!$B$10*SIN(RADIANS(F10)))
A11: mean ± SE | C11: =IFERROR(AVERAGE(C6:C10),"") | E11: =IFERROR(AVERAGE(E6:E10),"") | F11: =IFERROR(AVERAGE(F6:F10),"") | G11: =IFERROR(AVERAGE(G6:G10),"")
A12: SD / SE | F12: =IFERROR(STDEV(F6:F10),"") | G12: =IFERROR(STDEV(G6:G10)/SQRT(COUNT(G6:G10)),"")
A14: Glucose solution (10%)
A15: trial 1 | F15: =IF(C15="","",IF(D15=1,45-DEGREES(ASIN(SIN(RADIANS(C15))/Conditions!$B$10)),45+DEGREES(ASIN(SIN(RADIANS(C15))/Conditions!$B$10)))) | G15: =IF(F15="","",Conditions!$B$10*SIN(RADIANS(F15)))
A16: trial 2 | F16: =IF(C16="","",IF(D16=1,45-DEGREES(ASIN(SIN(RADIANS(C16))/Conditions!$B$10)),45+DEGREES(ASIN(SIN(RADIANS(C16))/Conditions!$B$10)))) | G16: =IF(F16="","",Conditions!$B$10*SIN(RADIANS(F16)))
A17: trial 3 | F17: =IF(C17="","",IF(D17=1,45-DEGREES(ASIN(SIN(RADIANS(C17))/Conditions!$B$10)),45+DEGREES(ASIN(SIN(RADIANS(C17))/Conditions!$B$10)))) | G17: =IF(F17="","",Conditions!$B$10*SIN(RADIANS(F17)))
A18: trial 4 | F18: =IF(C18="","",IF(D18=1,45-DEGREES(ASIN(SIN(RADIANS(C18))/Conditions!$B$10)),45+DEGREES(ASIN(SIN(RADIANS(C18))/Conditions!$B$10)))) | G18: =IF(F18="","",Conditions!$B$10*SIN(RADIANS(F18)))
A19: trial 5 | F19: =IF(C19="","",IF(D19=1,45-DEGREES(ASIN(SIN(RADIANS(C19))/Conditions!$B$10)),45+DEGREES(ASIN(SIN(RADIANS(C19))/Conditions!$B$10)))) | G19: =IF(F19="","",Conditions!$B$10*SIN(RADIANS(F19)))
A20: mean ± SE | C20: =IFERROR(AVERAGE(C15:C19),"") | E20: =IFERROR(AVERAGE(E15:E19),"") | F20: =IFERROR(AVERAGE(F15:F19),"") | G20: =IFERROR(AVERAGE(G15:G19),"")
A21: SD / SE | F21: =IFERROR(STDEV(F15:F19),"") | G21: =IFERROR(STDEV(G15:G19)/SQRT(COUNT(G15:G19)),"")
A23: Sodium chloride solution (10%)
A24: trial 1 | F24: =IF(C24="","",IF(D24=1,45-DEGREES(ASIN(SIN(RADIANS(C24))/Conditions!$B$10)),45+DEGREES(ASIN(SIN(RADIANS(C24))/Conditions!$B$10)))) | G24: =IF(F24="","",Conditions!$B$10*SIN(RADIANS(F24)))
A25: trial 2 | F25: =IF(C25="","",IF(D25=1,45-DEGREES(ASIN(SIN(RADIANS(C25))/Conditions!$B$10)),45+DEGREES(ASIN(SIN(RADIANS(C25))/Conditions!$B$10)))) | G25: =IF(F25="","",Conditions!$B$10*SIN(RADIANS(F25)))
A26: trial 3 | F26: =IF(C26="","",IF(D26=1,45-DEGREES(ASIN(SIN(RADIANS(C26))/Conditions!$B$10)),45+DEGREES(ASIN(SIN(RADIANS(C26))/Conditions!$B$10)))) | G26: =IF(F26="","",Conditions!$B$10*SIN(RADIANS(F26)))
A27: trial 4 | F27: =IF(C27="","",IF(D27=1,45-DEGREES(ASIN(SIN(RADIANS(C27))/Conditions!$B$10)),45+DEGREES(ASIN(SIN(RADIANS(C27))/Conditions!$B$10)))) | G27: =IF(F27="","",Conditions!$B$10*SIN(RADIANS(F27)))
A28: trial 5 | F28: =IF(C28="","",IF(D28=1,45-DEGREES(ASIN(SIN(RADIANS(C28))/Conditions!$B$10)),45+DEGREES(ASIN(SIN(RADIANS(C28))/Conditions!$B$10)))) | G28: =IF(F28="","",Conditions!$B$10*SIN(RADIANS(F28)))
A29: mean ± SE | C29: =IFERROR(AVERAGE(C24:C28),"") | E29: =IFERROR(AVERAGE(E24:E28),"") | F29: =IFERROR(AVERAGE(F24:F28),"") | G29: =IFERROR(AVERAGE(G24:G28),"")
A30: SD / SE | F30: =IFERROR(STDEV(F24:F28),"") | G30: =IFERROR(STDEV(G24:G28)/SQRT(COUNT(G24:G28)),"")
A32: Glycerol solution (20% w/w)
A33: trial 1 | F33: =IF(C33="","",IF(D33=1,45-DEGREES(ASIN(SIN(RADIANS(C33))/Conditions!$B$10)),45+DEGREES(ASIN(SIN(RADIANS(C33))/Conditions!$B$10)))) | G33: =IF(F33="","",Conditions!$B$10*SIN(RADIANS(F33)))
A34: trial 2 | F34: =IF(C34="","",IF(D34=1,45-DEGREES(ASIN(SIN(RADIANS(C34))/Conditions!$B$10)),45+DEGREES(ASIN(SIN(RADIANS(C34))/Conditions!$B$10)))) | G34: =IF(F34="","",Conditions!$B$10*SIN(RADIANS(F34)))
A35: trial 3 | F35: =IF(C35="","",IF(D35=1,45-DEGREES(ASIN(SIN(RADIANS(C35))/Conditions!$B$10)),45+DEGREES(ASIN(SIN(RADIANS(C35))/Conditions!$B$10)))) | G35: =IF(F35="","",Conditions!$B$10*SIN(RADIANS(F35)))
A36: trial 4 | F36: =IF(C36="","",IF(D36=1,45-DEGREES(ASIN(SIN(RADIANS(C36))/Conditions!$B$10)),45+DEGREES(ASIN(SIN(RADIANS(C36))/Conditions!$B$10)))) | G36: =IF(F36="","",Conditions!$B$10*SIN(RADIANS(F36)))
A37: trial 5 | F37: =IF(C37="","",IF(D37=1,45-DEGREES(ASIN(SIN(RADIANS(C37))/Conditions!$B$10)),45+DEGREES(ASIN(SIN(RADIANS(C37))/Conditions!$B$10)))) | G37: =IF(F37="","",Conditions!$B$10*SIN(RADIANS(F37)))
A38: mean ± SE | C38: =IFERROR(AVERAGE(C33:C37),"") | E38: =IFERROR(AVERAGE(E33:E37),"") | F38: =IFERROR(AVERAGE(F33:F37),"") | G38: =IFERROR(AVERAGE(G33:G37),"")
A39: SD / SE | F39: =IFERROR(STDEV(F33:F37),"") | G39: =IFERROR(STDEV(G33:G37)/SQRT(COUNT(G33:G37)),"")
A41: Olive oil
A42: trial 1 | F42: =IF(C42="","",IF(D42=1,45-DEGREES(ASIN(SIN(RADIANS(C42))/Conditions!$B$10)),45+DEGREES(ASIN(SIN(RADIANS(C42))/Conditions!$B$10)))) | G42: =IF(F42="","",Conditions!$B$10*SIN(RADIANS(F42)))
A43: trial 2 | F43: =IF(C43="","",IF(D43=1,45-DEGREES(ASIN(SIN(RADIANS(C43))/Conditions!$B$10)),45+DEGREES(ASIN(SIN(RADIANS(C43))/Conditions!$B$10)))) | G43: =IF(F43="","",Conditions!$B$10*SIN(RADIANS(F43)))
A44: trial 3 | F44: =IF(C44="","",IF(D44=1,45-DEGREES(ASIN(SIN(RADIANS(C44))/Conditions!$B$10)),45+DEGREES(ASIN(SIN(RADIANS(C44))/Conditions!$B$10)))) | G44: =IF(F44="","",Conditions!$B$10*SIN(RADIANS(F44)))
A45: trial 4 | F45: =IF(C45="","",IF(D45=1,45-DEGREES(ASIN(SIN(RADIANS(C45))/Conditions!$B$10)),45+DEGREES(ASIN(SIN(RADIANS(C45))/Conditions!$B$10)))) | G45: =IF(F45="","",Conditions!$B$10*SIN(RADIANS(F45)))
...

Sheet T1 summary
A1: Table 1 — as it should appear in the paper
A2: All formulas. Nothing to type here.
A4: Test liquid | B4: Mean critical angle θc /° | C4: Refractive index measured | D4: Accepted refractive index | E4: Deviation /%
A5: Deionised water | B5: =IFERROR('T1 raw readings'!F11&" ± "&TEXT('T1 raw readings'!G12,"0.0000"),"") -> ± | C5: =IFERROR('T1 raw readings'!E11,"") | D5: 1.333 | E5: =IFERROR(ABS(C5-D5)/D5*100,"")
A6: Glucose solution (10%) | B6: =IFERROR('T1 raw readings'!F20&" ± "&TEXT('T1 raw readings'!G21,"0.0000"),"") -> ± | C6: =IFERROR('T1 raw readings'!E20,"") | D6: 1.3477 | E6: =IFERROR(ABS(C6-D6)/D6*100,"")
A7: Sodium chloride solution (10%) | B7: =IFERROR('T1 raw readings'!F29&" ± "&TEXT('T1 raw readings'!G30,"0.0000"),"") -> ± | C7: =IFERROR('T1 raw readings'!E29,"") | D7: 1.3505 | E7: =IFERROR(ABS(C7-D7)/D7*100,"")
A8: Glycerol solution (20% w/w) | B8: =IFERROR('T1 raw readings'!F38&" ± "&TEXT('T1 raw readings'!G39,"0.0000"),"") -> ± | C8: =IFERROR('T1 raw readings'!E38,"") | D8: 1.36 | E8: =IFERROR(ABS(C8-D8)/D8*100,"")
A9: Olive oil | B9: =IFERROR('T1 raw readings'!F47&" ± "&TEXT('T1 raw readings'!G48,"0.0000"),"") -> ± | C9: =IFERROR('T1 raw readings'!E47,"") | D9: 1.47 | E9: =IFERROR(ABS(C9-D9)/D9*100,"")
A10: Mean deviation | E10: =IFERROR(AVERAGE(E5:E9),"")

Sheet T2 sucrose
A1: Table 2 — concentration mode
A2: Five trials per standard. The last standard is the hold-out: measure it but do NOT use it in the fit.
A4: Standard | B4: Concentration /% w/w | C4: n trial 1 | D4: n trial 2 | E4: n trial 3 | F4: n trial 4 | G4: n trial 5 | H4: Mean n | I4: SE | J4: Use in fit?
A5: Standard 1 | H5: =IFERROR(AVERAGE(C5:G5),"") | I5: =IFERROR(STDEV(C5:G5)/SQRT(COUNT(C5:G5)),"") | J5: yes
A6: Standard 2 | H6: =IFERROR(AVERAGE(C6:G6),"") | I6: =IFERROR(STDEV(C6:G6)/SQRT(COUNT(C6:G6)),"") | J6: yes
A7: Standard 3 | H7: =IFERROR(AVERAGE(C7:G7),"") | I7: =IFERROR(STDEV(C7:G7)/SQRT(COUNT(C7:G7)),"") | J7: yes
A8: Standard 4 | H8: =IFERROR(AVERAGE(C8:G8),"") | I8: =IFERROR(STDEV(C8:G8)/SQRT(COUNT(C8:G8)),"") | J8: yes
A9: Hold-out sample | H9: =IFERROR(AVERAGE(C9:G9),"") | I9: =IFERROR(STDEV(C9:G9)/SQRT(COUNT(C9:G9)),"") | J9: no
A11: Linear fit n = n₀ + k·c (standards 1–4 only)
A12: gradient k | B12: =IFERROR(SLOPE(H5:H8,B5:B8),"")
A13: intercept n₀ | B13: =IFERROR(INTERCEPT(H5:H8,B5:B8),"")
A14: R² | B14: =IFERROR(RSQ(H5:H8,B5:B8),"")
A16: Hold-out test — the only independent check in the paper
A17: true concentration /% w/w | B17: =IF(B9="","",B9)
A18: concentration returned from fit | B18: =IFERROR((H9-B13)/B12,"")
A19: error /% w/w | B19: =IFERROR(B18-B17,"")

Sheet T3 bill of materials
A1: Table 3 — bill of materials
A2: From receipts only. If you cannot evidence a number, leave it blank rather than estimating.
A4: Component | B4: Quantity | C4: Unit cost /S$ | D4: Subtotal /S$ | E4: Source / receipt
A5: 589 nm sodium laser | D5: =IF(OR(B5="",C5=""),"",B5*C5)
A6: Right-angled isosceles prism | D6: =IF(OR(B6="",C6=""),"",B6*C6)
A7: Stepper motor and ULN2003 driver | D7: =IF(OR(B7="",C7=""),"",B7*C7)
A8: Slip ring | D8: =IF(OR(B8="",C8=""),"",B8*C8)
A9: Arduino microcontroller | D9: =IF(OR(B9="",C9=""),"",B9*C9)
A10: LDR, resistors and connecting wire | D10: =IF(OR(B10="",C10=""),"",B10*C10)
A11: 16×2 LCD display | D11: =IF(OR(B11="",C11=""),"",B11*C11)
A12: Numeric keypad | D12: =IF(OR(B12="",C12=""),"",B12*C12)
A13: Rocker switch | D13: =IF(OR(B13="",C13=""),"",B13*C13)
A14: PLA filament (housing, stage, cell) | D14: =IF(OR(B14="",C14=""),"",B14*C14)
A15: Total as built | D15: =IFERROR(SUM(D5:D14),"") -> 0
A16: Commodity laser diode (replacement cost)
A17: Total with commodity diode | D17: =IFERROR(D15-D5+C16,"")

Sheet Conditions
A1: Instrument and session details
A3: Quantity | B3: Value | C3: Note
A4: Number of trials per liquid | B4: 5 | C4: Fixed at 5 by your teacher's instruction
A5: Room temperature /°C | C5: Record with a thermometer; refractive index is temperature dependent
A6: Device length /mm | C6: Measure the finished direct-drive build, not the CAD model
A7: Device width /mm
A8: Device height /mm
A9: Device mass /g | C9: Kitchen scale is fine
A10: Prism refractive index n_P | B10: 1.5 | C10: Used by every formula in this workbook. Change here if you measure it.
A11: Steps per output revolution | B11: 4076 | C11: 28BYJ-48: 32 × 2 × 63.68395 = 4075.77
A12: Degrees per step | B12: =IFERROR(360/B11,"") -> 0.088321884 | C12: computed

Sheet Precision rules
A1: How many decimal places each quantity may honestly carry
A3: Quantity | B3: Report as | C3: Why
A4: Stage angle φ, incident α | B4: 0.0001° | C4: As printed by the firmware. Raw record only — do not quote in the paper.
A5: Critical angle θc (mean) | B5: match the SE | C5: Round the mean to the same decimal place as its standard error.
A6: Standard error on θc | B6: 1 significant figure | C6: With n = 5 the SE is itself uncertain by about ±35%; more digits are noise.
A7: Refractive index, single trial | B7: 0.00001 | C7: What the device prints. Appendix A only.
A8: Refractive index, mean | B8: 0.0001 | C8: One motor step ≈ 0.0007 in n, and the edge fit resolves below one step.
A9: Refractive index — ACCURACY | B9: 0.01 | C9: Limited by n_P = 1.50 (3 s.f.). A 0.67% error there is ±0.009 in n.
A10: Deviation from accepted value | B10: 0.01 % | C10: Supported only if the mean n is quoted to 4 d.p.
A11: Accepted reference values | B11: as published | C11: Cite the source; do not add digits the reference does not have.
A12: Concentration | B12: 0.1 % w/w | C12: Set by how accurately you can weigh and make up the standards.
A13: Cost | B13: 0.01 S$ | C13: From receipts.
A14: Dimensions | B14: 1 mm (ruler) or 0.1 mm (calipers) | C14: Match the instrument you actually used.
A15: Temperature | B15: 0.1 °C | C15: If your thermometer reads to 0.1. Otherwise 1 °C.
A17: THE DISTINCTION YOUR TEACHER IS PROBABLY TESTING
A18: Precision (repeatability) is what the five trials show — the spread of your own readings.
A19: Accuracy is how close you are to the true value, and it is capped by the assumed prism index.
A20: You can legitimately quote a very repeatable mean to 4 d.p. while admitting the accuracy is only ±0.01.
A21: Those are different claims and the paper must not blur them.
